<?xml version="1.0"?>
<robot name="mini_pupper">
  <material name="yellow"><color rgba="1 0.8 0 1"/></material>
  <material name="black"><color rgba="0.1 0.1 0.1 1"/></material>

  <link name="base_link">
    <visual>
      <origin xyz="0 0 0" rpy="0 0 0"/>
      <geometry><mesh filename="meshes/base.stl"/></geometry>
      <material name="yellow"/>
    </visual>

    <collision>
      <origin xyz="0 0 0.03500" rpy="0 0 0"/>
      <geometry><box size="0.18110 0.07000 0.07000"/></geometry>
    </collision>

    <inertial>
      <origin xyz="0 0 0.03500" rpy="0 0 0"/>
      <mass value="0.56000"/>
      <inertia ixx="0.00045733" ixy="0" ixz="0" iyy="0.00175920" iyz="0" izz="0.00175920"/>
    </inertial>
  </link>

  <joint name="lf_hip_joint" type="revolute">
    <parent link="base_link"/>
    <child link="lf_hip"/>
    <origin xyz="0.06000 0.03500 0.01710" rpy="0 0 0"/>
    <axis xyz="1 0 0"/>
    <limit lower="-0.8" upper="0.8" effort="12.0" velocity="10.0"/>
  </joint>

  <link name="lf_hip">
    <visual>
      <origin xyz="0 0 0" rpy="0 0 0"/>
      <geometry><mesh filename="meshes/lf_hip.stl"/></geometry>
      <material name="black"/>
    </visual>
    <collision>
      <origin xyz="0 0 0" rpy="1.57079632679 0 0"/>
      <geometry><cylinder radius="0.015" length="0.04"/></geometry>
    </collision>
    <inertial>
      <mass value="0.08"/>
      <inertia ixx="0.00010" ixy="0" ixz="0" iyy="0.00010" iyz="0" izz="0.00010"/>
    </inertial>
  </link>

  <joint name="lf_thigh_joint" type="revolute">
    <parent link="lf_hip"/>
    <child link="lf_thigh"/>
    <origin xyz="0 0.01970 0" rpy="0 0 0"/>
    <axis xyz="0 1 0"/>
    <limit lower="-1.5" upper="1.5" effort="12.0" velocity="10.0"/>
  </joint>

  <link name="lf_thigh">
    <visual>
      <origin xyz="0 0 0" rpy="0 0 0"/>
      <geometry><mesh filename="meshes/lf_upper_leg.stl"/></geometry>
      <material name="yellow"/>
    </visual>
    <collision>
      <origin xyz="0 0 -0.025" rpy="0 0 0"/>
      <geometry><box size="0.02 0.01 0.05"/></geometry>
    </collision>
    <inertial>
      <mass value="0.08"/>
      <inertia ixx="0.00010" ixy="0" ixz="0" iyy="0.00010" iyz="0" izz="0.00010"/>
    </inertial>
  </link>

  <joint name="lf_calf_joint" type="revolute">
    <parent link="lf_thigh"/>
    <child link="lf_calf"/>
    <origin xyz="0 0.00475 -0.05" rpy="0 0 0"/>
    <axis xyz="0 1 0"/>
    <limit lower="-2.5" upper="0.5" effort="12.0" velocity="10.0"/>
  </joint>

  <link name="lf_calf">
    <visual>
      <origin xyz="0 0 0" rpy="0 0 0"/>
      <geometry><mesh filename="meshes/lf_lower_leg.stl"/></geometry>
      <material name="black"/>
    </visual>
    <collision>
      <origin xyz="0 0 -0.03" rpy="0 0 0"/>
      <geometry><box size="0.015 0.01 0.06"/></geometry>
    </collision>
    <inertial>
      <mass value="0.04"/>
      <inertia ixx="0.00002" ixy="0" ixz="0" iyy="0.00002" iyz="0" izz="0.00002"/>
    </inertial>
  </link>

  <joint name="lf_foot_fixed" type="fixed">
    <parent link="lf_calf"/>
    <child link="lf_foot"/>
    <origin xyz="0 0 -0.056" rpy="0 0 0"/>
  </joint>

  <link name="lf_foot">
    <visual>
      <origin xyz="0 0 0" rpy="0 0 0"/>
      <geometry><mesh filename="meshes/foot.stl"/></geometry>
      <material name="black"/>
    </visual>
    <collision>
      <origin xyz="0 0 0" rpy="0 0 0"/>
      <geometry><sphere radius="0.012"/></geometry>
    </collision>
    <inertial>
      <mass value="0.01"/>
      <inertia ixx="0.000001" ixy="0" ixz="0" iyy="0.000001" iyz="0" izz="0.000001"/>
    </inertial>
  </link>

  <joint name="lh_hip_joint" type="revolute">
    <parent link="base_link"/>
    <child link="lh_hip"/>
    <origin xyz="-0.06000 0.03500 0.01710" rpy="0 0 0"/>
    <axis xyz="1 0 0"/>
    <limit lower="-0.8" upper="0.8" effort="12.0" velocity="10.0"/>
  </joint>

  <link name="lh_hip">
    <visual>
      <origin xyz="0 0 0" rpy="0 0 0"/>
      <geometry><mesh filename="meshes/lh_hip.stl"/></geometry>
      <material name="black"/>
    </visual>
    <collision>
      <origin xyz="0 0 0" rpy="1.57079632679 0 0"/>
      <geometry><cylinder radius="0.015" length="0.04"/></geometry>
    </collision>
    <inertial>
      <mass value="0.08"/>
      <inertia ixx="0.00010" ixy="0" ixz="0" iyy="0.00010" iyz="0" izz="0.00010"/>
    </inertial>
  </link>

  <joint name="lh_thigh_joint" type="revolute">
    <parent link="lh_hip"/>
    <child link="lh_thigh"/>
    <origin xyz="0 0.01970 0" rpy="0 0 0"/>
    <axis xyz="0 1 0"/>
    <limit lower="-1.5" upper="1.5" effort="12.0" velocity="10.0"/>
  </joint>

  <link name="lh_thigh">
    <visual>
      <origin xyz="0 0 0" rpy="0 0 0"/>
      <geometry><mesh filename="meshes/lh_upper_leg.stl"/></geometry>
      <material name="yellow"/>
    </visual>
    <collision>
      <origin xyz="0 0 -0.025" rpy="0 0 0"/>
      <geometry><box size="0.02 0.01 0.05"/></geometry>
    </collision>
    <inertial>
      <mass value="0.08"/>
      <inertia ixx="0.00010" ixy="0" ixz="0" iyy="0.00010" iyz="0" izz="0.00010"/>
    </inertial>
  </link>

  <joint name="lh_calf_joint" type="revolute">
    <parent link="lh_thigh"/>
    <child link="lh_calf"/>
    <origin xyz="0 0.00475 -0.05" rpy="0 0 0"/>
    <axis xyz="0 1 0"/>
    <limit lower="-2.5" upper="0.5" effort="12.0" velocity="10.0"/>
  </joint>

  <link name="lh_calf">
    <visual>
      <origin xyz="0 0 0" rpy="0 0 0"/>
      <geometry><mesh filename="meshes/lh_lower_leg.stl"/></geometry>
      <material name="black"/>
    </visual>
    <collision>
      <origin xyz="0 0 -0.03" rpy="0 0 0"/>
      <geometry><box size="0.015 0.01 0.06"/></geometry>
    </collision>
    <inertial>
      <mass value="0.04"/>
      <inertia ixx="0.00002" ixy="0" ixz="0" iyy="0.00002" iyz="0" izz="0.00002"/>
    </inertial>
  </link>

  <joint name="lh_foot_fixed" type="fixed">
    <parent link="lh_calf"/>
    <child link="lh_foot"/>
    <origin xyz="0 0 -0.056" rpy="0 0 0"/>
  </joint>

  <link name="lh_foot">
    <visual>
      <origin xyz="0 0 0" rpy="0 0 0"/>
      <geometry><mesh filename="meshes/foot.stl"/></geometry>
      <material name="black"/>
    </visual>
    <collision>
      <origin xyz="0 0 0" rpy="0 0 0"/>
      <geometry><sphere radius="0.012"/></geometry>
    </collision>
    <inertial>
      <mass value="0.01"/>
      <inertia ixx="0.000001" ixy="0" ixz="0" iyy="0.000001" iyz="0" izz="0.000001"/>
    </inertial>
  </link>

  <joint name="rf_hip_joint" type="revolute">
    <parent link="base_link"/>
    <child link="rf_hip"/>
    <origin xyz="0.06000 -0.03500 0.01710" rpy="0 0 0"/>
    <axis xyz="1 0 0"/>
    <limit lower="-0.8" upper="0.8" effort="12.0" velocity="10.0"/>
  </joint>

  <link name="rf_hip">
    <visual>
      <origin xyz="0 0 0" rpy="0 0 0"/>
      <geometry><mesh filename="meshes/rf_hip.stl"/></geometry>
      <material name="black"/>
    </visual>
    <collision>
      <origin xyz="0 0 0" rpy="1.57079632679 0 0"/>
      <geometry><cylinder radius="0.015" length="0.04"/></geometry>
    </collision>
    <inertial>
      <mass value="0.08"/>
      <inertia ixx="0.00010" ixy="0" ixz="0" iyy="0.00010" iyz="0" izz="0.00010"/>
    </inertial>
  </link>

  <joint name="rf_thigh_joint" type="revolute">
    <parent link="rf_hip"/>
    <child link="rf_thigh"/>
    <origin xyz="0 -0.01970 0" rpy="0 0 0"/>
    <axis xyz="0 1 0"/>
    <limit lower="-1.5" upper="1.5" effort="12.0" velocity="10.0"/>
  </joint>

  <link name="rf_thigh">
    <visual>
      <origin xyz="0 0 0" rpy="0 0 0"/>
      <geometry><mesh filename="meshes/rf_upper_leg.stl"/></geometry>
      <material name="yellow"/>
    </visual>
    <collision>
      <origin xyz="0 0 -0.025" rpy="0 0 0"/>
      <geometry><box size="0.02 0.01 0.05"/></geometry>
    </collision>
    <inertial>
      <mass value="0.08"/>
      <inertia ixx="0.00010" ixy="0" ixz="0" iyy="0.00010" iyz="0" izz="0.00010"/>
    </inertial>
  </link>

  <joint name="rf_calf_joint" type="revolute">
    <parent link="rf_thigh"/>
    <child link="rf_calf"/>
    <origin xyz="0 -0.00475 -0.05" rpy="0 0 0"/>
    <axis xyz="0 1 0"/>
    <limit lower="-2.5" upper="0.5" effort="12.0" velocity="10.0"/>
  </joint>

  <link name="rf_calf">
    <visual>
      <origin xyz="0 0 0" rpy="0 0 0"/>
      <geometry><mesh filename="meshes/rf_lower_leg.stl"/></geometry>
      <material name="black"/>
    </visual>
    <collision>
      <origin xyz="0 0 -0.03" rpy="0 0 0"/>
      <geometry><box size="0.015 0.01 0.06"/></geometry>
    </collision>
    <inertial>
      <mass value="0.04"/>
      <inertia ixx="0.00002" ixy="0" ixz="0" iyy="0.00002" iyz="0" izz="0.00002"/>
    </inertial>
  </link>

  <joint name="rf_foot_fixed" type="fixed">
    <parent link="rf_calf"/>
    <child link="rf_foot"/>
    <origin xyz="0 0 -0.056" rpy="0 0 0"/>
  </joint>

  <link name="rf_foot">
    <visual>
      <origin xyz="0 0 0" rpy="0 0 0"/>
      <geometry><mesh filename="meshes/foot.stl"/></geometry>
      <material name="black"/>
    </visual>
    <collision>
      <origin xyz="0 0 0" rpy="0 0 0"/>
      <geometry><sphere radius="0.012"/></geometry>
    </collision>
    <inertial>
      <mass value="0.01"/>
      <inertia ixx="0.000001" ixy="0" ixz="0" iyy="0.000001" iyz="0" izz="0.000001"/>
    </inertial>
  </link>

  <joint name="rh_hip_joint" type="revolute">
    <parent link="base_link"/>
    <child link="rh_hip"/>
    <origin xyz="-0.06000 -0.03500 0.01710" rpy="0 0 0"/>
    <axis xyz="1 0 0"/>
    <limit lower="-0.8" upper="0.8" effort="12.0" velocity="10.0"/>
  </joint>

  <link name="rh_hip">
    <visual>
      <origin xyz="0 0 0" rpy="0 0 0"/>
      <geometry><mesh filename="meshes/rh_hip.stl"/></geometry>
      <material name="black"/>
    </visual>
    <collision>
      <origin xyz="0 0 0" rpy="1.57079632679 0 0"/>
      <geometry><cylinder radius="0.015" length="0.04"/></geometry>
    </collision>
    <inertial>
      <mass value="0.08"/>
      <inertia ixx="0.00010" ixy="0" ixz="0" iyy="0.00010" iyz="0" izz="0.00010"/>
    </inertial>
  </link>

  <joint name="rh_thigh_joint" type="revolute">
    <parent link="rh_hip"/>
    <child link="rh_thigh"/>
    <origin xyz="0 -0.01970 0" rpy="0 0 0"/>
    <axis xyz="0 1 0"/>
    <limit lower="-1.5" upper="1.5" effort="12.0" velocity="10.0"/>
  </joint>

  <link name="rh_thigh">
    <visual>
      <origin xyz="0 0 0" rpy="0 0 0"/>
      <geometry><mesh filename="meshes/rh_upper_leg.stl"/></geometry>
      <material name="yellow"/>
    </visual>
    <collision>
      <origin xyz="0 0 -0.025" rpy="0 0 0"/>
      <geometry><box size="0.02 0.01 0.05"/></geometry>
    </collision>
    <inertial>
      <mass value="0.08"/>
      <inertia ixx="0.00010" ixy="0" ixz="0" iyy="0.00010" iyz="0" izz="0.00010"/>
    </inertial>
  </link>

  <joint name="rh_calf_joint" type="revolute">
    <parent link="rh_thigh"/>
    <child link="rh_calf"/>
    <origin xyz="0 -0.00475 -0.05" rpy="0 0 0"/>
    <axis xyz="0 1 0"/>
    <limit lower="-2.5" upper="0.5" effort="12.0" velocity="10.0"/>
  </joint>

  <link name="rh_calf">
    <visual>
      <origin xyz="0 0 0" rpy="0 0 0"/>
      <geometry><mesh filename="meshes/rh_lower_leg.stl"/></geometry>
      <material name="black"/>
    </visual>
    <collision>
      <origin xyz="0 0 -0.03" rpy="0 0 0"/>
      <geometry><box size="0.015 0.01 0.06"/></geometry>
    </collision>
    <inertial>
      <mass value="0.04"/>
      <inertia ixx="0.00002" ixy="0" ixz="0" iyy="0.00002" iyz="0" izz="0.00002"/>
    </inertial>
  </link>

  <joint name="rh_foot_fixed" type="fixed">
    <parent link="rh_calf"/>
    <child link="rh_foot"/>
    <origin xyz="0 0 -0.056" rpy="0 0 0"/>
  </joint>

  <link name="rh_foot">
    <visual>
      <origin xyz="0 0 0" rpy="0 0 0"/>
      <geometry><mesh filename="meshes/foot.stl"/></geometry>
      <material name="black"/>
    </visual>
    <collision>
      <origin xyz="0 0 0" rpy="0 0 0"/>
      <geometry><sphere radius="0.012"/></geometry>
    </collision>
    <inertial>
      <mass value="0.01"/>
      <inertia ixx="0.000001" ixy="0" ixz="0" iyy="0.000001" iyz="0" izz="0.000001"/>
    </inertial>
  </link>

  <joint name="camera_joint" type="fixed">
    <parent link="base_link"/>
    <child link="camera_link"/>
    <origin xyz="0.09055 0 0.07000" rpy="0 0.26180 0"/>
  </joint>

  <link name="camera_link">
    <visual>
      <origin xyz="0 0 0" rpy="0 0 0"/>
      <geometry>
        <box size="0.01 0.02 0.02"/>
      </geometry>
      <material name="black"/>
    </visual>
    <inertial>
      <mass value="0.01"/>
      <inertia ixx="0.000001" ixy="0" ixz="0" iyy="0.000001" iyz="0" izz="0.000001"/>
    </inertial>
  </link>

</robot>
